<?xml version="1.0" ?>
<!-- =================================================================================== -->
<!-- |    This document was autogenerated by xacro from /home/galois/projects/cells_ws/src/hrc_case_study_cell/hrc_case_study/hrc_case_study_descriptions/urdf/sharework_cembre_simplified.xacro | -->
<!-- |    EDITING THIS FILE BY HAND IS NOT RECOMMENDED                                 | -->
<!-- =================================================================================== -->
<robot name="sharework_cembre_simplified">
    <material name="aluminum">
        <color rgba="0.5 0.5 0.5 1" />
    </material>
    <material name="plastic">
        <color rgba="0.1 0.1 0.1 1" />
    </material>
    <!-- <xacro:include filename="$(find robotiq_2f_85_gripper_visualization)/urdf/robotiq_arg2f_85_model_macro.xacro" /> -->
    <link name="world" />
    <joint name="base_to_right_leg" type="fixed">
        <parent link="world" />
        <child link="portal" />
        <origin xyz="0 0 0" />
    </joint>
    <!-- PORTAL -->
    <link name="portal" />
    <joint name="portal_to_right_column" type="fixed">
        <parent link="world" />
        <child link="right_column" />
        <origin xyz="-0.58 1.0 0" />
    </joint>
    <joint name="portal_to_left_column" type="fixed">
        <parent link="world" />
        <child link="left_column" />
        <origin xyz="-0.58 -1.0 0" />
    </joint>
    <link name="right_column">
        <visual>
            <origin rpy="0 0 0" xyz="0.29 0.06 1.5" />
            <geometry>
                <box size="0.58 0.12 3.0" />
            </geometry>
            <material name="Grey">
                <color rgba="0.517647058823529 0.529411764705882 0.537254901960784 1" />
            </material>
        </visual>
        <collision>
            <origin rpy="0 0 0" xyz="0.29 0.06 1.5" />
            <geometry>
                <box size="0.6599999999999999 0.2 3.0" />
            </geometry>
            <material name="Grey">
                <color rgba="0.517647058823529 0.529411764705882 0.537254901960784 1" />
            </material>
        </collision>
        <inertial>
            <mass value="0.1" />
            <origin xyz="0 0 0" rpy="0 0 0" />
            <inertia ixx="0.03" iyy="0.03" izz="0.03" ixy="0.0" ixz="0.0" iyz="0.0" />
        </inertial>
    </link>
    <link name="left_column">
        <visual>
            <origin rpy="0 0 0" xyz="0.29 -0.06 1.5" />
            <geometry>
                <box size="0.58 0.12 3.0" />
            </geometry>
            <material name="Grey">
                <color rgba="0.517647058823529 0.529411764705882 0.537254901960784 1" />
            </material>
        </visual>
        <collision>
            <origin rpy="0 0 0" xyz="0.29 -0.06 1.5" />
            <geometry>
                <box size="0.6599999999999999 0.2 3.0" />
            </geometry>
            <material name="Grey">
                <color rgba="0.517647058823529 0.529411764705882 0.537254901960784 1" />
            </material>
        </collision>
        <inertial>
            <mass value="0.1" />
            <origin xyz="0 0 0" rpy="0 0 0" />
            <inertia ixx="0.03" iyy="0.03" izz="0.03" ixy="0.0" ixz="0.0" iyz="0.0" />
        </inertial>
    </link>
    <joint name="portal_to_lower_beam" type="fixed">
        <parent link="world" />
        <child link="lower_beam" />
        <origin xyz="-0.58 0 0.895" />
    </joint>
    <link name="lower_beam">
        <visual>
            <origin rpy="0 0 0" xyz="0.29 0 -0.048" />
            <geometry>
                <box size="0.58 2.0 0.12" />
            </geometry>
            <material name="Grey">
                <color rgba="0.517647058823529 0.529411764705882 0.537254901960784 1" />
            </material>
        </visual>
        <collision>
            <origin rpy="0 0 0" xyz="0.29 0 -0.048" />
            <geometry>
                <box size="0.58 2.0 0.12" />
            </geometry>
            <material name="Grey">
                <color rgba="0.517647058823529 0.529411764705882 0.537254901960784 1" />
            </material>
        </collision>
        <inertial>
            <mass value="0.1" />
            <origin xyz="0 0 0" rpy="0 0 0" />
            <inertia ixx="0.03" iyy="0.03" izz="0.03" ixy="0.0" ixz="0.0" iyz="0.0" />
        </inertial>
    </link>
    <joint name="portal_to_upper_beam" type="fixed">
        <parent link="world" />
        <child link="upper_beam" />
        <origin xyz="-0.58 0 2.208" />
    </joint>
    <link name="upper_beam">
        <visual>
            <origin rpy="0 0 0" xyz="0.29 0 0.06" />
            <geometry>
                <box size="0.58 2.0 0.12" />
            </geometry>
            <material name="Grey">
                <color rgba="0.517647058823529 0.529411764705882 0.537254901960784 1" />
            </material>
        </visual>
        <collision>
            <origin rpy="0 0 0" xyz="0.29 0 0.06" />
            <geometry>
                <box size="0.58 2.0 0.12" />
            </geometry>
            <material name="Grey">
                <color rgba="0.517647058823529 0.529411764705882 0.537254901960784 1" />
            </material>
        </collision>
        <inertial>
            <mass value="0.1" />
            <origin xyz="0 0 0" rpy="0 0 0" />
            <inertia ixx="0.03" iyy="0.03" izz="0.03" ixy="0.0" ixz="0.0" iyz="0.0" />
        </inertial>
    </link>
    <!-- guide -->
    <joint name="upper_beam_guide" type="fixed">
        <parent link="upper_beam" />
        <child link="guide_fixed" />
        <origin xyz="0.325 -1.0 -0.14" />
    </joint>
    <link name="guide_fixed">
        <visual>
            <origin rpy="0 0 0" xyz="0 1.0 0.07" />
            <geometry>
                <box size="0.28 2.0 0.14" />
            </geometry>
            <material name="Grey">
                <color rgba="0.517647058823529 0.529411764705882 0.537254901960784 1" />
            </material>
        </visual>
        <collision>
            <origin rpy="0 0 0" xyz="0 1.0 0.07" />
            <geometry>
                <box size="0.5800000000000001 2.0 0.14" />
            </geometry>
            <material name="Grey">
                <color rgba="0.517647058823529 0.529411764705882 0.537254901960784 1" />
            </material>
        </collision>
        <inertial>
            <mass value="0.1" />
            <origin xyz="0 0 0" rpy="0 0 0" />
            <inertia ixx="0.03" iyy="0.03" izz="0.03" ixy="0.0" ixz="0.0" iyz="0.0" />
        </inertial>
    </link>
    <joint name="track_joint" type="fixed">
        <parent link="guide_fixed" />
        <child link="cursor" />
        <origin xyz="0 1.061 -0.01" />
        <limit effort="1000.0" lower="0" upper="1.4" velocity="0.5" />
        <axis xyz="0 1 0" />
    </joint>
    <link name="cursor">
        <visual>
            <origin rpy="0 0 0" xyz="0 0 0.005" />
            <geometry>
                <box size="0.28 0.28 0.01" />
            </geometry>
            <material name="DarkGrey">
                <color rgba="0.1 0.1 0.1 1" />
            </material>
        </visual>
        <collision>
            <origin rpy="0 0 0" xyz="0 0 0.005" />
            <geometry>
                <box size="0.28 0.28 0.01" />
            </geometry>
            <material name="DarkGrey">
                <color rgba="0.1 0.1 0.1 1" />
            </material>
        </collision>
        <inertial>
            <mass value="0.1" />
            <origin xyz="0 0 0" rpy="0 0 0" />
            <inertia ixx="0.03" iyy="0.03" izz="0.03" ixy="0.0" ixz="0.0" iyz="0.0" />
        </inertial>
    </link>
    <!-- TABLE -->
    <joint name="portal_to_table" type="fixed">
        <parent link="world" />
        <child link="table" />
        <origin xyz="0 -1.0 0.895" />
    </joint>
    <link name="table">
        <visual>
            <origin rpy="0 0 0" xyz="0.3 1.0 -0.02" />
            <geometry>
                <box size="0.6 2.0 0.04" />
            </geometry>
            <material name="Beech">
                <color rgba="0.952941176470588 0.694117647058823 0.392156862745098 1" />
            </material>
        </visual>
        <collision>
            <origin rpy="0 0 0" xyz="0.3 1.0 -0.02" />
            <geometry>
                <box size="0.6 2.0 0.04" />
            </geometry>
            <material name="Beech">
                <color rgba="0.952941176470588 0.694117647058823 0.392156862745098 1" />
            </material>
        </collision>
        <inertial>
            <mass value="0.1" />
            <origin xyz="0 0 0" rpy="0 0 0" />
            <inertia ixx="0.03" iyy="0.03" izz="0.03" ixy="0.0" ixz="0.0" iyz="0.0" />
        </inertial>
    </link>
    <joint name="table_to_rail" type="fixed">
        <parent link="table" />
        <child link="rail" />
        <origin xyz="0.3 -0.6120000000000001 0.12" />
    </joint>
    <link name="rail">
        <visual>
            <origin rpy="0 0 0" xyz="0 1.612 -0.06" />
            <geometry>
                <box size="0.36 3.224 0.12" />
            </geometry>
            <material name="Grey">
                <color rgba="0.517647058823529 0.529411764705882 0.537254901960784 1" />
            </material>
        </visual>
        <collision>
            <origin rpy="0 0 0" xyz="0 1.612 -0.06" />
            <geometry>
                <box size="0.36 3.224 0.12" />
            </geometry>
            <material name="Grey">
                <color rgba="0.517647058823529 0.529411764705882 0.537254901960784 1" />
            </material>
        </collision>
        <inertial>
            <mass value="0.1" />
            <origin xyz="0 0 0" rpy="0 0 0" />
            <inertia ixx="0.03" iyy="0.03" izz="0.03" ixy="0.0" ixz="0.0" iyz="0.0" />
        </inertial>
    </link>
    <!--
    Base UR robot series xacro macro.

    NOTE: this is NOT a URDF. It cannot directly be loaded by consumers
    expecting a flattened '.urdf' file. See the top-level '.xacro' for that
    (but note: that .xacro must still be processed by the xacro command).

    For use in '.launch' files: use one of the 'load_urX.launch' convenience
    launch files.

    This file models the base kinematic chain of a UR robot, which then gets
    parameterised by various configuration files to convert it into a UR3(e),
    UR5(e), UR10(e) or UR16e.

    NOTE: the default kinematic parameters (ie: link lengths, frame locations,
    offets, etc) do not correspond to any particular robot. They are defaults
    only. There WILL be non-zero offsets between the Forward Kinematics results
    in TF (ie: robot_state_publisher) and the values reported by the Teach
    Pendant.

    For accurate (and robot-specific) transforms, the 'kinematics_parameters_file'
    parameter MUST point to a .yaml file containing the appropriate values for
    the targetted robot.

    If using the UniversalRobots/Universal_Robots_ROS_Driver, follow the steps
    described in the readme of that repository to extract the kinematic
    calibration from the controller and generate the required .yaml file.

    Main author of the migration to yaml configs: Ludovic Delval.

    Contributors to previous versions (in no particular order):

     - Felix Messmer
     - Kelsey Hawkins
     - Wim Meeussen
     - Shaun Edwards
     - Nadia Hammoudeh Garcia
     - Dave Hershberger
     - G. vd. Hoorn
     - Philip Long
     - Dave Coleman
     - Miguel Prada
     - Mathias Luedtke
     - Marcel Schnirring
     - Felix von Drigalski
     - Felix Exner
     - Jimmy Da Silva
     - Ajit Krisshna N L
     - Muhammad Asif Rana
  -->
    <!--
    NOTE: the macro defined in this file is NOT part of the public API of this
          package. Users CANNOT rely on this file being available, or stored in
          this location. Nor can they rely on the existence of the macro.
  -->
    <transmission name="shoulder_pan_trans">
        <type>transmission_interface/SimpleTransmission</type>
        <joint name="shoulder_pan_joint">
            <hardwareInterface>hardware_interface/PositionJointInterface</hardwareInterface>
        </joint>
        <actuator name="shoulder_pan_motor">
            <mechanicalReduction>1</mechanicalReduction>
            <hardwareInterface>hardware_interface/EffortJointInterface</hardwareInterface>
        </actuator>
    </transmission>
    <transmission name="shoulder_lift_trans">
        <type>transmission_interface/SimpleTransmission</type>
        <joint name="shoulder_lift_joint">
            <hardwareInterface>hardware_interface/PositionJointInterface</hardwareInterface>
        </joint>
        <actuator name="shoulder_lift_motor">
            <mechanicalReduction>1</mechanicalReduction>
            <hardwareInterface>hardware_interface/EffortJointInterface</hardwareInterface>
        </actuator>
    </transmission>
    <transmission name="elbow_trans">
        <type>transmission_interface/SimpleTransmission</type>
        <joint name="elbow_joint">
            <hardwareInterface>hardware_interface/PositionJointInterface</hardwareInterface>
        </joint>
        <actuator name="elbow_motor">
            <mechanicalReduction>1</mechanicalReduction>
            <hardwareInterface>hardware_interface/EffortJointInterface</hardwareInterface>
        </actuator>
    </transmission>
    <transmission name="wrist_1_trans">
        <type>transmission_interface/SimpleTransmission</type>
        <joint name="wrist_1_joint">
            <hardwareInterface>hardware_interface/PositionJointInterface</hardwareInterface>
        </joint>
        <actuator name="wrist_1_motor">
            <mechanicalReduction>1</mechanicalReduction>
            <hardwareInterface>hardware_interface/EffortJointInterface</hardwareInterface>
        </actuator>
    </transmission>
    <transmission name="wrist_2_trans">
        <type>transmission_interface/SimpleTransmission</type>
        <joint name="wrist_2_joint">
            <hardwareInterface>hardware_interface/PositionJointInterface</hardwareInterface>
        </joint>
        <actuator name="wrist_2_motor">
            <mechanicalReduction>1</mechanicalReduction>
            <hardwareInterface>hardware_interface/EffortJointInterface</hardwareInterface>
        </actuator>
    </transmission>
    <transmission name="wrist_3_trans">
        <type>transmission_interface/SimpleTransmission</type>
        <joint name="wrist_3_joint">
            <hardwareInterface>hardware_interface/PositionJointInterface</hardwareInterface>
        </joint>
        <actuator name="wrist_3_motor">
            <mechanicalReduction>1</mechanicalReduction>
            <hardwareInterface>hardware_interface/EffortJointInterface</hardwareInterface>
        </actuator>
    </transmission>
    <!-- links: main serial chain -->
    <link name="base_link" />
    <link name="base_link_inertia">
        <visual>
            <origin rpy="0 0 3.141592653589793" xyz="0 0 0" />
            <geometry>
                <mesh filename="package://ur_description/meshes/ur10e/visual/base.dae" />
            </geometry>
            <material name="LightGrey">
                <color rgba="0.7 0.7 0.7 1.0" />
            </material>
        </visual>
        <collision>
            <origin rpy="0 0 3.141592653589793" xyz="0 0 0" />
            <geometry>
                <mesh filename="package://ur_simplified_description/meshes/ur10e/collision/base.STL" />
            </geometry>
        </collision>
        <inertial>
            <mass value="4.0" />
            <origin rpy="0 0 0" xyz="0 0 0" />
            <inertia ixx="0.0061063308908" ixy="0.0" ixz="0.0" iyy="0.0061063308908" iyz="0.0" izz="0.01125" />
        </inertial>
    </link>
    <link name="shoulder_link">
        <visual>
            <origin rpy="0 0 3.141592653589793" xyz="0 0 0" />
            <geometry>
                <mesh filename="package://ur_description/meshes/ur10e/visual/shoulder.dae" />
            </geometry>
            <material name="LightGrey">
                <color rgba="0.7 0.7 0.7 1.0" />
            </material>
        </visual>
        <collision>
            <origin rpy="0 0 3.141592653589793" xyz="0 0 0" />
            <geometry>
                <mesh filename="package://ur_simplified_description/meshes/ur10e/collision/shoulder.STL" />
            </geometry>
        </collision>
        <inertial>
            <mass value="7.778" />
            <origin rpy="0 0 0" xyz="0 0 0" />
            <inertia ixx="0.03147431257693659" ixy="0.0" ixz="0.0" iyy="0.03147431257693659" iyz="0.0" izz="0.021875624999999996" />
        </inertial>
    </link>
    <link name="upper_arm_link">
        <visual>
            <origin rpy="1.5707963267948966 0 -1.5707963267948966" xyz="0 0 0.1762" />
            <geometry>
                <mesh filename="package://ur_description/meshes/ur10e/visual/upperarm.dae" />
            </geometry>
            <material name="LightGrey">
                <color rgba="0.7 0.7 0.7 1.0" />
            </material>
        </visual>
        <collision>
            <origin rpy="1.5707963267948966 0 -1.5707963267948966" xyz="0 0 0.1762" />
            <geometry>
                <mesh filename="package://ur_simplified_description/meshes/ur10e/collision/upperarm.STL" />
            </geometry>
        </collision>
        <inertial>
            <mass value="12.93" />
            <origin rpy="0 1.5707963267948966 0" xyz="-0.306 0.0 0.175" />
            <inertia ixx="0.42175380379841093" ixy="0.0" ixz="0.0" iyy="0.42175380379841093" iyz="0.0" izz="0.03636562499999999" />
        </inertial>
    </link>
    <link name="forearm_link">
        <visual>
            <origin rpy="1.5707963267948966 0 -1.5707963267948966" xyz="0 0 0.0393" />
            <geometry>
                <mesh filename="package://ur_description/meshes/ur10e/visual/forearm.dae" />
            </geometry>
            <material name="LightGrey">
                <color rgba="0.7 0.7 0.7 1.0" />
            </material>
        </visual>
        <collision>
            <origin rpy="1.5707963267948966 0 -1.5707963267948966" xyz="0 0 0.0393" />
            <geometry>
                <mesh filename="package://ur_simplified_description/meshes/ur10e/collision/forearm.STL" />
            </geometry>
        </collision>
        <inertial>
            <mass value="3.87" />
            <origin rpy="0 1.5707963267948966 0" xyz="-0.285775 0.0 0.0393" />
            <inertia ixx="0.11079302548902206" ixy="0.0" ixz="0.0" iyy="0.11079302548902206" iyz="0.0" izz="0.010884375" />
        </inertial>
    </link>
    <link name="wrist_1_link">
        <visual>
            <!-- TODO: Move this to a parameter -->
            <origin rpy="1.5707963267948966 0 0" xyz="0 0 -0.135" />
            <geometry>
                <mesh filename="package://ur_description/meshes/ur10e/visual/wrist1.dae" />
            </geometry>
            <material name="LightGrey">
                <color rgba="0.7 0.7 0.7 1.0" />
            </material>
        </visual>
        <collision>
            <origin rpy="1.5707963267948966 0 0" xyz="0 0 -0.135" />
            <geometry>
                <mesh filename="package://ur_simplified_description/meshes/ur10e/collision/wrist1.STL" />
            </geometry>
        </collision>
        <inertial>
            <mass value="1.96" />
            <origin rpy="0 0 0" xyz="0 0 0" />
            <inertia ixx="0.005108247956699999" ixy="0.0" ixz="0.0" iyy="0.005108247956699999" iyz="0.0" izz="0.005512499999999999" />
        </inertial>
    </link>
    <link name="wrist_2_link">
        <visual>
            <origin rpy="0 0 0" xyz="0 0 -0.12" />
            <geometry>
                <mesh filename="package://ur_description/meshes/ur10e/visual/wrist2.dae" />
            </geometry>
            <material name="LightGrey">
                <color rgba="0.7 0.7 0.7 1.0" />
            </material>
        </visual>
        <collision>
            <origin rpy="0 0 0" xyz="0 0 -0.12" />
            <geometry>
                <mesh filename="package://ur_simplified_description/meshes/ur10e/collision/wrist2.STL" />
            </geometry>
        </collision>
        <inertial>
            <mass value="1.96" />
            <origin rpy="0 0 0" xyz="0 0 0" />
            <inertia ixx="0.005108247956699999" ixy="0.0" ixz="0.0" iyy="0.005108247956699999" iyz="0.0" izz="0.005512499999999999" />
        </inertial>
    </link>
    <link name="wrist_3_link">
        <visual>
            <origin rpy="1.5707963267948966 0 0" xyz="0 0 -0.1168" />
            <geometry>
                <mesh filename="package://ur_description/meshes/ur10e/visual/wrist3.dae" />
            </geometry>
            <material name="LightGrey">
                <color rgba="0.7 0.7 0.7 1.0" />
            </material>
        </visual>
        <collision>
            <origin rpy="1.5707963267948966 0 0" xyz="0 0 -0.1168" />
            <geometry>
                <mesh filename="package://ur_simplified_description/meshes/ur10e/collision/wrist3.STL" />
            </geometry>
        </collision>
        <inertial>
            <mass value="0.202" />
            <origin rpy="0 0 0" xyz="0.0 0.0 -0.025" />
            <inertia ixx="0.00014434577559500002" ixy="0.0" ixz="0.0" iyy="0.00014434577559500002" iyz="0.0" izz="0.00020452500000000002" />
        </inertial>
    </link>
    <!-- joints: main serial chain -->
    <joint name="base_link-base_link_inertia" type="fixed">
        <parent link="base_link" />
        <child link="base_link_inertia" />
        <!-- 'base_link' is REP-103 aligned (so X+ forward), while the internal
           frames of the robot/controller have X+ pointing backwards.
           Use the joint between 'base_link' and 'base_link_inertia' (a dummy
           link/frame) to introduce the necessary rotation over Z (of pi rad).
      -->
        <origin rpy="0 0 3.141592653589793" xyz="0 0 0" />
    </joint>
    <joint name="shoulder_pan_joint" type="revolute">
        <parent link="base_link_inertia" />
        <child link="shoulder_link" />
        <origin rpy="0 0 -5.681537116101164e-08" xyz="0 0 0.1812369595612139" />
        <axis xyz="0 0 1" />
        <limit effort="330.0" lower="-3.141592653589793" upper="3.141592653589793" velocity="2.0943951023931953" />
        <dynamics damping="0" friction="0" />
    </joint>
    <joint name="shoulder_lift_joint" type="revolute">
        <parent link="shoulder_link" />
        <child link="upper_arm_link" />
        <origin rpy="1.571234322931965 0 -2.65322894683893e-06" xyz="-8.792654051589253e-05 0 0" />
        <axis xyz="0 0 1" />
        <limit effort="330.0" lower="-3.141592653589793" upper="0.05235987755982989" velocity="2.0943951023931953" />
        <dynamics damping="0" friction="0" />
    </joint>
    <joint name="elbow_joint" type="revolute">
        <parent link="upper_arm_link" />
        <child link="forearm_link" />
        <origin rpy="0.0006685683672481053 0.0009626857853689462 2.732284048217955e-06" xyz="-0.6121801947349813 0 0" />
        <axis xyz="0 0 1" />
        <limit effort="150.0" lower="-3.141592653589793" upper="3.141592653589793" velocity="3.141592653589793" />
        <dynamics damping="0" friction="0" />
    </joint>
    <joint name="wrist_1_joint" type="revolute">
        <parent link="forearm_link" />
        <child link="wrist_1_link" />
        <origin rpy="3.139891413463903 3.140677396542519 3.141591156697404" xyz="-0.5709010104944168 0.0002966689356048516 0.1743837597536871" />
        <axis xyz="0 0 1" />
        <limit effort="56.0" lower="-6.283185307179586" upper="6.283185307179586" velocity="3.141592653589793" />
        <dynamics damping="0" friction="0" />
    </joint>
    <joint name="wrist_2_joint" type="revolute">
        <parent link="wrist_1_link" />
        <child link="wrist_2_link" />
        <origin rpy="1.57098614732238 0 1.097571004999014e-06" xyz="4.867185823864961e-05 -0.1198472927249651 -2.274947659575111e-05" />
        <axis xyz="0 0 1" />
        <limit effort="56.0" lower="-6.283185307179586" upper="6.283185307179586" velocity="3.141592653589793" />
        <dynamics damping="0" friction="0" />
    </joint>
    <joint name="wrist_3_joint" type="revolute">
        <parent link="wrist_2_link" />
        <child link="wrist_3_link" />
        <origin rpy="1.57076096219631 3.141592653589793 3.141592581057134" xyz="-0.0001284994478715255 0.1156303551619035 -4.089221096405905e-06" />
        <axis xyz="0 0 1" />
        <limit effort="56.0" lower="-6.283185307179586" upper="6.283185307179586" velocity="3.141592653589793" />
        <dynamics damping="0" friction="0" />
    </joint>
    <!-- ROS-Industrial 'base' frame: base_link to UR 'Base' Coordinates transform -->
    <link name="base" />
    <joint name="base_link-base_fixed_joint" type="fixed">
        <!-- Note the rotation over Z of pi radians: as base_link is REP-103
           aligned (ie: has X+ forward, Y+ left and Z+ up), this is needed
           to correctly align 'base' with the 'Base' coordinate system of
           the UR controller.
      -->
        <origin rpy="0 0 3.141592653589793" xyz="0 0 0" />
        <parent link="base_link" />
        <child link="base" />
    </joint>
    <!-- ROS-Industrial 'flange' frame: attachment point for EEF models -->
    <link name="flange" />
    <joint name="wrist_3-flange" type="fixed">
        <parent link="wrist_3_link" />
        <child link="flange" />
        <origin rpy="0 -1.5707963267948966 -1.5707963267948966" xyz="0 0 0" />
    </joint>
    <!-- ROS-Industrial 'tool0' frame: all-zeros tool frame -->
    <link name="tool0" />
    <joint name="flange-tool0" type="fixed">
        <!-- default toolframe: X+ left, Y+ up, Z+ front -->
        <origin rpy="1.5707963267948966 0 1.5707963267948966" xyz="0 0 0" />
        <parent link="flange" />
        <child link="tool0" />
    </joint>
    <link name="robotiq_arg2f_base_link">
        <!-- <inertial>
        <origin xyz="8.625E-08 -4.6583E-06 0.03145" rpy="0 0 0" />
        <mass value="0.22652" />
        <inertia ixx="0.00020005" ixy="-4.2442E-10" ixz="-2.9069E-10" iyy="0.00017832" iyz="-3.4402E-08" izz="0.00013478" />
      </inertial> -->
        <visual>
            <origin rpy="0 0 0" xyz="0 0 0" />
            <geometry>
                <mesh filename="package://robotiq_2f_85_gripper_visualization/meshes/visual/robotiq_arg2f_85_base_link.dae" scale="0.001 0.001 0.001" />
            </geometry>
            <material name="">
                <color rgba="0.1 0.1 0.1 1" />
            </material>
        </visual>
        <!-- <collision>
        <geometry>
          <cylinder length="0.0" radius="0.0"/>         
        </geometry>
      </collision> -->
    </link>
    <link name="left_outer_knuckle">
        <!--<inertial>
        <origin xyz="-0.000200000000003065 0.0199435877845359 0.0292245259211331" rpy="0 0 0" />
        <mass value="0.00853198276973456" />
        <inertia ixx="2.89328108496468E-06" ixy="-1.57935047237397E-19" ixz="-1.93980378593255E-19" iyy="1.86719750325683E-06" iyz="-1.21858577871576E-06" izz="1.21905238907251E-06" />
        </inertial> -->
        <visual>
            <origin rpy="0 0 0" xyz="0 0 0" />
            <geometry>
                <mesh filename="package://robotiq_2f_85_gripper_visualization/meshes/visual/robotiq_arg2f_85_outer_knuckle.dae" scale="0.001 0.001 0.001" />
            </geometry>
            <material name="">
                <color rgba="0.792156862745098 0.819607843137255 0.933333333333333 1" />
            </material>
        </visual>
        <!-- <collision>
        <geometry>
          <cylinder length="0.0" radius="0.0"/>          
            <cylinder length="0.0" radius="0.0"/>         
        </geometry>
      </collision> -->
    </link>
    <link name="left_outer_finger">
        <!--<inertial>
        <origin xyz="0.00030115855001899 0.0373907951953854 -0.0208027427000385" rpy="0 0 0" />
        <mass value="0.022614240507152" />
        <inertia ixx="1.52518312458174E-05" ixy="9.76583423954399E-10" ixz="-5.43838577022588E-10" iyy="6.17694243867776E-06" iyz="6.78636130740228E-06" izz="1.16494917907219E-05" />
        </inertial> -->
        <visual>
            <origin rpy="0 0 0" xyz="0 0 0" />
            <geometry>
                <mesh filename="package://robotiq_2f_85_gripper_visualization/meshes/visual/robotiq_arg2f_85_outer_finger.dae" scale="0.001 0.001 0.001" />
            </geometry>
            <material name="">
                <color rgba="0.1 0.1 0.1 1" />
            </material>
        </visual>
        <!-- <collision>
        <geometry>
            <cylinder length="0.0" radius="0.0"/>        
        </geometry>
      </collision> -->
    </link>
    <link name="left_inner_finger">
        <!--<inertial>
        <origin xyz="0.000299999999999317 0.0160078233491243 -0.0136945669206257" rpy="0 0 0" />
        <mass value="0.0104003125914103" />
        <inertia ixx="2.71909453810972E-06" ixy="1.35402465472579E-21" ixz="-7.1817349065269E-22" iyy="7.69100314106116E-07" iyz="6.74715432769696E-07" izz="2.30315190420171E-06" />
        </inertial> -->
        <visual>
            <origin rpy="0 0 0" xyz="0 0 0" />
            <geometry>
                <mesh filename="package://robotiq_2f_85_gripper_visualization/meshes/visual/robotiq_arg2f_85_inner_finger.dae" scale="0.001 0.001 0.001" />
            </geometry>
            <material name="">
                <color rgba="0.1 0.1 0.1 1" />
            </material>
        </visual>
        <!-- <collision>
        <geometry>
          <cylinder length="0.0" radius="0.0"/>         
        </geometry>
      </collision> -->
    </link>
    <link name="left_inner_finger_pad">
        <visual>
            <origin rpy="0 0 0" xyz="0 0 0" />
            <geometry>
                <box size="0.022 0.00635 0.0375" />
            </geometry>
            <material name="">
                <color rgba="0.9 0.9 0.9 1" />
            </material>
        </visual>
        <!-- <collision>
        <geometry>
          <cylinder length="0.0" radius="0.0"/>      
        </geometry>
      </collision> -->
    </link>
    <link name="left_inner_knuckle">
        <!--<inertial>
        <origin xyz="0.000123011831763771 0.0507850843201817 0.00103968640075166" rpy="0 0 0" />
       <mass value="0.0271177346495152" />
        <inertia ixx="2.61910379223783E-05" ixy="-2.43616858946494E-07" ixz="-6.37789906117123E-09" iyy="2.8270243746167E-06" iyz="-5.37200748039765E-07" izz="2.83695868220296E-05" />
        </inertial> -->
        <visual>
            <origin rpy="0 0 0" xyz="0 0 0" />
            <geometry>
                <mesh filename="package://robotiq_2f_85_gripper_visualization/meshes/visual/robotiq_arg2f_85_inner_knuckle.dae" scale="0.001 0.001 0.001" />
            </geometry>
            <material name="">
                <color rgba="0.1 0.1 0.1 1" />
            </material>
        </visual>
        <!-- <collision>
        <geometry>
          <cylinder length="0.0" radius="0.0"/>         
        </geometry>
      </collision>  -->
    </link>
    <link name="right_outer_knuckle">
        <!--<inertial>
        <origin xyz="-0.000200000000003065 0.0199435877845359 0.0292245259211331" rpy="0 0 0" />
        <mass value="0.00853198276973456" />
        <inertia ixx="2.89328108496468E-06" ixy="-1.57935047237397E-19" ixz="-1.93980378593255E-19" iyy="1.86719750325683E-06" iyz="-1.21858577871576E-06" izz="1.21905238907251E-06" />
        </inertial> -->
        <visual>
            <origin rpy="0 0 0" xyz="0 0 0" />
            <geometry>
                <mesh filename="package://robotiq_2f_85_gripper_visualization/meshes/visual/robotiq_arg2f_85_outer_knuckle.dae" scale="0.001 0.001 0.001" />
            </geometry>
            <material name="">
                <color rgba="0.792156862745098 0.819607843137255 0.933333333333333 1" />
            </material>
        </visual>
        <!-- <collision>
        <geometry>
          <cylinder length="0.0" radius="0.0"/>          
            <cylinder length="0.0" radius="0.0"/>         
        </geometry>
      </collision> -->
    </link>
    <link name="right_outer_finger">
        <!--<inertial>
        <origin xyz="0.00030115855001899 0.0373907951953854 -0.0208027427000385" rpy="0 0 0" />
        <mass value="0.022614240507152" />
        <inertia ixx="1.52518312458174E-05" ixy="9.76583423954399E-10" ixz="-5.43838577022588E-10" iyy="6.17694243867776E-06" iyz="6.78636130740228E-06" izz="1.16494917907219E-05" />
        </inertial> -->
        <visual>
            <origin rpy="0 0 0" xyz="0 0 0" />
            <geometry>
                <mesh filename="package://robotiq_2f_85_gripper_visualization/meshes/visual/robotiq_arg2f_85_outer_finger.dae" scale="0.001 0.001 0.001" />
            </geometry>
            <material name="">
                <color rgba="0.1 0.1 0.1 1" />
            </material>
        </visual>
        <!-- <collision>
        <geometry>
            <cylinder length="0.0" radius="0.0"/>        
        </geometry>
      </collision> -->
    </link>
    <link name="right_inner_finger">
        <!--<inertial>
        <origin xyz="0.000299999999999317 0.0160078233491243 -0.0136945669206257" rpy="0 0 0" />
        <mass value="0.0104003125914103" />
        <inertia ixx="2.71909453810972E-06" ixy="1.35402465472579E-21" ixz="-7.1817349065269E-22" iyy="7.69100314106116E-07" iyz="6.74715432769696E-07" izz="2.30315190420171E-06" />
        </inertial> -->
        <visual>
            <origin rpy="0 0 0" xyz="0 0 0" />
            <geometry>
                <mesh filename="package://robotiq_2f_85_gripper_visualization/meshes/visual/robotiq_arg2f_85_inner_finger.dae" scale="0.001 0.001 0.001" />
            </geometry>
            <material name="">
                <color rgba="0.1 0.1 0.1 1" />
            </material>
        </visual>
        <!-- <collision>
        <geometry>
          <cylinder length="0.0" radius="0.0"/>         
        </geometry>
      </collision> -->
    </link>
    <link name="right_inner_finger_pad">
        <visual>
            <origin rpy="0 0 0" xyz="0 0 0" />
            <geometry>
                <box size="0.022 0.00635 0.0375" />
            </geometry>
            <material name="">
                <color rgba="0.9 0.9 0.9 1" />
            </material>
        </visual>
        <!-- <collision>
        <geometry>
          <cylinder length="0.0" radius="0.0"/>      
        </geometry>
      </collision> -->
    </link>
    <link name="right_inner_knuckle">
        <!--<inertial>
        <origin xyz="0.000123011831763771 0.0507850843201817 0.00103968640075166" rpy="0 0 0" />
       <mass value="0.0271177346495152" />
        <inertia ixx="2.61910379223783E-05" ixy="-2.43616858946494E-07" ixz="-6.37789906117123E-09" iyy="2.8270243746167E-06" iyz="-5.37200748039765E-07" izz="2.83695868220296E-05" />
        </inertial> -->
        <visual>
            <origin rpy="0 0 0" xyz="0 0 0" />
            <geometry>
                <mesh filename="package://robotiq_2f_85_gripper_visualization/meshes/visual/robotiq_arg2f_85_inner_knuckle.dae" scale="0.001 0.001 0.001" />
            </geometry>
            <material name="">
                <color rgba="0.1 0.1 0.1 1" />
            </material>
        </visual>
        <!-- <collision>
        <geometry>
          <cylinder length="0.0" radius="0.0"/>         
        </geometry>
      </collision>  -->
    </link>
    <joint name="finger_joint" type="fixed">
        <origin rpy="0 0 3.141592653589793" xyz="0 -0.0306011 0.054904" />
        <parent link="robotiq_arg2f_base_link" />
        <child link="left_outer_knuckle" />
        <axis xyz="1 0 0" />
        <limit effort="1000" lower="0" upper="0.8" velocity="2.0" />
    </joint>
    <joint name="left_outer_finger_joint" type="fixed">
        <origin rpy="0 0 0" xyz="0 0.0315 -0.0041" />
        <parent link="left_outer_knuckle" />
        <child link="left_outer_finger" />
        <axis xyz="1 0 0" />
    </joint>
    <joint name="left_inner_knuckle_joint" type="fixed">
        <!-- <origin xyz="0 ${reflect * -0.0127} 0.06142" rpy="${pi / 2 + .725} 0 ${(reflect - 1) * pi / 2}" /> -->
        <origin rpy="0 0 3.141592653589793" xyz="0 -0.0127 0.06142" />
        <parent link="robotiq_arg2f_base_link" />
        <child link="left_inner_knuckle" />
        <axis xyz="1 0 0" />
        <limit effort="1000" lower="0" upper="0.8757" velocity="2.0" />
        <mimic joint="finger_joint" multiplier="1" offset="0" />
    </joint>
    <joint name="left_inner_finger_joint" type="fixed">
        <origin rpy="0 0 0" xyz="0 0.0061 0.0471" />
        <parent link="left_outer_finger" />
        <child link="left_inner_finger" />
        <axis xyz="1 0 0" />
        <limit effort="1000" lower="0" upper="0.8757" velocity="2.0" />
        <mimic joint="finger_joint" multiplier="-1" offset="0" />
    </joint>
    <joint name="left_inner_finger_pad_joint" type="fixed">
        <origin rpy="0 0 0" xyz="0 -0.0220203446692936 0.03242" />
        <parent link="left_inner_finger" />
        <child link="left_inner_finger_pad" />
        <axis xyz="0 0 1" />
    </joint>
    <joint name="right_outer_knuckle_joint" type="fixed">
        <origin rpy="0 0 0" xyz="0 0.0306011 0.054904" />
        <parent link="robotiq_arg2f_base_link" />
        <child link="right_outer_knuckle" />
        <axis xyz="1 0 0" />
        <limit effort="1000" lower="0" upper="0.81" velocity="2.0" />
        <mimic joint="finger_joint" multiplier="1" offset="0" />
    </joint>
    <joint name="right_outer_finger_joint" type="fixed">
        <origin rpy="0 0 0" xyz="0 0.0315 -0.0041" />
        <parent link="right_outer_knuckle" />
        <child link="right_outer_finger" />
        <axis xyz="1 0 0" />
    </joint>
    <joint name="right_inner_knuckle_joint" type="fixed">
        <!-- <origin xyz="0 ${reflect * -0.0127} 0.06142" rpy="${pi / 2 + .725} 0 ${(reflect - 1) * pi / 2}" /> -->
        <origin rpy="0 0 0.0" xyz="0 0.0127 0.06142" />
        <parent link="robotiq_arg2f_base_link" />
        <child link="right_inner_knuckle" />
        <axis xyz="1 0 0" />
        <limit effort="1000" lower="0" upper="0.8757" velocity="2.0" />
        <mimic joint="finger_joint" multiplier="1" offset="0" />
    </joint>
    <joint name="right_inner_finger_joint" type="fixed">
        <origin rpy="0 0 0" xyz="0 0.0061 0.0471" />
        <parent link="right_outer_finger" />
        <child link="right_inner_finger" />
        <axis xyz="1 0 0" />
        <limit effort="1000" lower="0" upper="0.8757" velocity="2.0" />
        <mimic joint="finger_joint" multiplier="-1" offset="0" />
    </joint>
    <joint name="right_inner_finger_pad_joint" type="fixed">
        <origin rpy="0 0 0" xyz="0 -0.0220203446692936 0.03242" />
        <parent link="right_inner_finger" />
        <child link="right_inner_finger_pad" />
        <axis xyz="0 0 1" />
    </joint>
    <transmission name="finger_joint_trans">
        <type>transmission_interface/SimpleTransmission</type>
        <joint name="finger_joint">
            <hardwareInterface>PositionJointInterface</hardwareInterface>
        </joint>
        <actuator name="finger_joint_motor">
            <mechanicalReduction>1</mechanicalReduction>
        </actuator>
    </transmission>
    <!-- gripper -->
    <joint name="rq_coupler_joint" type="fixed">
        <parent link="tool0" />
        <child link="robotiq_coupler" />
        <origin rpy="0 0 1.5707963267948966" xyz="0 0 0.01" />
    </joint>
    <link name="robotiq_coupler">
        <visual>
            <origin rpy="0 0 0" xyz="0 0 0.005" />
            <geometry>
                <cylinder length="0.01" radius="0.0375" />
            </geometry>
            <material name="RobotiqGrey">
                <color rgba="0.1 0.1 0.1 1" />
            </material>
        </visual>
        <collision>
            <origin rpy="0 0 0" xyz="0 0 0.02" />
            <geometry>
                <cylinder length="0.04" radius="0.0375" />
            </geometry>
            <material name="RobotiqGrey">
                <color rgba="0.1 0.1 0.1 1" />
            </material>
        </collision>
        <inertial>
            <mass value="0.5" />
            <inertia ixx="0.1" ixy="0.0" ixz="0.0" iyy="0.1" iyz="0.0" izz="0.4" />
            <origin xyz="0 0 0" rpy="0 0 0" />
        </inertial>
    </link>
    <!-- <xacro:robotiq_arg2f_base_link prefix=""/>
  <xacro:finger_joints prefix=""/>
  <xacro:finger_links prefix=""/>

  <xacro:finger_joints fingerprefix=""/>
  <xacro:finger_joints reflect="1"/>

  <xacro:finger_links fingerprefix=""/>
  <xacro:finger_links stroke="0.05"/> -->
    <joint name="robotiq_joint" type="fixed">
        <parent link="robotiq_coupler" />
        <child link="robotiq_arg2f_base_link" />
        <origin rpy="0 0 0.0" xyz="0.0 0.0 0.0" />
    </joint>
    <link name="robotiq_simplified">
        <inertial>
            <origin rpy="0 0 0" xyz="8.625E-08 -4.6583E-06 0.03145" />
            <mass value="0.22652" />
            <inertia ixx="0.00020005" ixy="-4.2442E-10" ixz="-2.9069E-10" iyy="0.00017832" iyz="-3.4402E-08" izz="0.00013478" />
        </inertial>
        <collision>
            <origin rpy="0 0 0" xyz="0 0 0.045" />
            <geometry>
                <box size="0.035 0.145 0.09" />
            </geometry>
            <material name="RobotiqGrey">
                <color rgba="0.1 0.1 0.1 1" />
            </material>
        </collision>
        <collision>
            <origin rpy="0 0 0" xyz="0 0.055 0.08" />
            <geometry>
                <box size="0.035 0.03 0.16" />
            </geometry>
            <material name="RobotiqGrey">
                <color rgba="0.1 0.1 0.1 1" />
            </material>
        </collision>
        <collision>
            <origin rpy="0 0 0" xyz="0 -0.055 0.08" />
            <geometry>
                <box size="0.035 0.03 0.16" />
            </geometry>
            <material name="RobotiqGrey">
                <color rgba="0.1 0.1 0.1 1" />
            </material>
        </collision>
    </link>
    <joint name="robotiq_joint_simplified" type="fixed">
        <parent link="robotiq_coupler" />
        <child link="robotiq_simplified" />
        <origin rpy="0 0 0.0" xyz="0.0 0.0 0.0" />
    </joint>
    <link name="open_tip" />
    <joint name="open_tip_joint" type="fixed">
        <parent link="robotiq_coupler" />
        <child link="open_tip" />
        <origin rpy="0 0 1.5707963267948966" xyz="0 0 0.149" />
    </joint>
    <link name="closed_tip" />
    <joint name="closed_tip_joint" type="fixed">
        <parent link="robotiq_coupler" />
        <child link="closed_tip" />
        <origin rpy="0 0 1.5707963267948966" xyz="0 0 0.163" />
    </joint>
    <joint name="rq_connector_joint" type="fixed">
        <parent link="robotiq_coupler" />
        <child link="rq_connector" />
        <origin rpy="0 0 0" xyz="-0.06 0 0" />
    </joint>
    <link name="rq_connector">
        <visual>
            <origin rpy="0 0 0" xyz="0 0 0" />
            <geometry>
                <box size="0.02 0.02 0.04" />
            </geometry>
            <material name="White">
                <color rgba="1 1 1 1" />
            </material>
        </visual>
        <collision>
            <origin rpy="0 0 0" xyz="0 0 0" />
            <geometry>
                <box size="0.02 0.02 0.04" />
            </geometry>
            <material name="White">
                <color rgba="1 1 1 1" />
            </material>
        </collision>
        <inertial>
            <mass value="0.1" />
            <origin xyz="0 0 0" rpy="0 0 0" />
            <inertia ixx="0.03" iyy="0.03" izz="0.03" ixy="0.0" ixz="0.0" iyz="0.0" />
        </inertial>
    </link>
    <joint name="cursor_to_base" type="fixed">
        <parent link="cursor" />
        <child link="base_link" />
        <origin rpy="3.141592653589793 0.0 1.5707963267948966" xyz="0.0 0.0 0.0" />
    </joint>
    <!-- walls  -->
    <joint name="portal_to_wall" type="fixed">
        <parent link="portal" />
        <child link="wall" />
        <origin xyz="-0.98 0 0" />
    </joint>
    <link name="wall">
        <visual>
            <origin rpy="0 0 0" xyz="-0.05 0 1.5" />
            <geometry>
                <box size="0.1 4.24 3.0" />
            </geometry>
            <material name="White">
                <color rgba="1 1 1 1" />
            </material>
        </visual>
        <collision>
            <origin rpy="0 0 0" xyz="-0.05 0 1.5" />
            <geometry>
                <box size="0.1 4.24 3.0" />
            </geometry>
            <material name="White">
                <color rgba="1 1 1 1" />
            </material>
        </collision>
        <inertial>
            <mass value="0.1" />
            <origin xyz="0 0 0" rpy="0 0 0" />
            <inertia ixx="0.03" iyy="0.03" izz="0.03" ixy="0.0" ixz="0.0" iyz="0.0" />
        </inertial>
    </link>
    <!-- <joint name="wall_to_ec" type="fixed">
    <parent link="wall"/>
    <child link="electric_cabinet"/>
    <origin xyz="0 ${table_size_x*0.5} 0"/>
</joint>

<link name="electric_cabinet">
   <visual>
     <origin xyz="${0.5*ec_size_x} ${0.5*ec_size_y} ${0.5*ec_size_z}" rpy="0 0 0" />
     <geometry>
       <box size="${ec_size_x} ${ec_size_y} ${ec_size_z}" />
     </geometry>
     <material name="White">
       <color rgba="1 1 1 1"/>
     </material>
   </visual>
   <collision>
     <origin xyz="${0.5*ec_size_x} ${0.5*ec_size_y} ${0.5*ec_size_z}" rpy="0 0 0" />
     <geometry>
       <box size="${ec_size_x} ${ec_size_y} ${ec_size_z}" />
     </geometry>
     <material name="White">
       <color rgba="1 1 1 1"/>
     </material>
   </collision>
</link> -->
    <joint name="portal_to_floor" type="fixed">
        <parent link="portal" />
        <child link="floor" />
        <origin xyz="-0.98 0 0" />
    </joint>
    <link name="floor">
        <visual>
            <origin rpy="0 0 0" xyz="2.02 0 -0.005" />
            <geometry>
                <box size="6 6 0.81" />
            </geometry>
            <material name="White">
                <color rgba="1 1 1 0.1" />
            </material>
        </visual>
    </link>
    <!-- Screw driver -->
    <joint name="table_to_screwdriver_holder" type="fixed">
        <parent link="table" />
        <child link="screwdriver_holder" />
        <origin xyz="0.2 -0.05 1.5" />
    </joint>
    <link name="screwdriver_holder">
        <visual>
            <origin rpy="0 0 0" xyz="0 0 0" />
            <geometry>
                <box size="0.4 0.2 1.5" />
            </geometry>
            <material name="White">
                <color rgba="1 1 1 1" />
            </material>
        </visual>
        <collision>
            <origin rpy="0 0 0" xyz="0 0 0" />
            <geometry>
                <box size="0.2 0.2 2" />
            </geometry>
            <material name="White">
                <color rgba="1 1 1 1" />
            </material>
        </collision>
        <inertial>
            <mass value="0.1" />
            <origin xyz="0 0 0" rpy="0 0 0" />
            <inertia ixx="0.03" iyy="0.03" izz="0.03" ixy="0.0" ixz="0.0" iyz="0.0" />
        </inertial>
    </link>
    <!-- Virtual Wall -->
    <joint name="virtual_wall_1_joint" type="fixed">
        <parent link="guide_fixed" />
        <child link="virtual_wall_1" />
        <origin xyz="0 0 0.0" />
    </joint>
    <link name="virtual_wall_1">
        <collision>
            <origin rpy="0 0 0" xyz="-0.5 1.0 0.0005" />
            <geometry>
                <box size="1.58 2.24 0.001" />
            </geometry>
            <material name="VirtualWallColor">
                <color rgba="0.1 0.1 0.1 0.1" />
            </material>
        </collision>
        <inertial>
            <mass value="0.1" />
            <origin xyz="0 0 0" rpy="0 0 0" />
            <inertia ixx="0.03" iyy="0.03" izz="0.03" ixy="0.0" ixz="0.0" iyz="0.0" />
        </inertial>
    </link>
    <joint name="virtual_wall_2_joint" type="fixed">
        <parent link="world" />
        <child link="virtual_wall_2" />
        <origin xyz="1.7000000000000002 0 0.0" />
    </joint>
    <link name="virtual_wall_2">
        <collision>
            <origin rpy="0 0 0" xyz="0.0005 0 1" />
            <geometry>
                <box size="0.001 2.24 2" />
            </geometry>
            <material name="VirtualWallColor2">
                <color rgba="0.1 0.1 0.1 0.1" />
            </material>
        </collision>
        <inertial>
            <mass value="0.1" />
            <origin xyz="0 0 0" rpy="0 0 0" />
            <inertia ixx="0.03" iyy="0.03" izz="0.03" ixy="0.0" ixz="0.0" iyz="0.0" />
        </inertial>
    </link>
    <joint name="base_working_table" type="fixed">
        <parent link="world" />
        <child link="working_table_with_wheels_link" />
        <origin rpy="0 0 -1.57079632679" xyz="1.5 -1.5 0" />
    </joint>
    <link name="working_table_with_wheels_link">
        <inertial>
            <origin rpy="0 0 0" xyz="0.2503 0.50105 0.67682" />
            <mass value="37.726" />
            <inertia ixx="6.0362" ixy="0.012989" ixz="0.0016097" iyy="2.7997" iyz="-0.0022709" izz="5.507" />
        </inertial>
        <visual>
            <origin rpy="0 0 0" xyz="0 0 0" />
            <geometry>
                <mesh filename="package://hrc_case_study_descriptions/mesh/working_table_with_wheels.STL" scale="0.001 0.001 0.001" />
            </geometry>
            <material name="">
                <color rgba="1 1 1 1" />
            </material>
        </visual>
        <collision>
            <origin rpy="0 0 0" xyz="0 0 0" />
            <geometry>
                <mesh filename="package://hrc_case_study_descriptions/mesh/working_table_with_wheels.STL" scale="0.001 0.001 0.001" />
            </geometry>
        </collision>
    </link>
    <joint name="working_table_top" type="fixed">
        <origin rpy="0 0 0" xyz="-0.01757 -0.016679 1.1096" />
        <parent link="working_table_with_wheels_link" />
        <child link="working_table_top_link" />
        <axis xyz="0 0 0" />
    </joint>
    <link name="working_table_top_link" />
    <!-- Util link for user bottles pack -->
    <joint name="user_bottles_util" type="fixed">
        <parent link="working_table_top_link" />
        <child link="user_bottles_link" />
        <origin xyz="0.2 0.4 0.0" />
    </joint>
    <link name="user_bottles_link" />
    <!-- Call the pack macro in order to create the bottles pack with the config specified in the yaml -->
    <!-- <xacro:pack parent_link_name="user_bottles_link" pack_name="user_pack" yaml_file_name="${user_pack_yaml_file_name}" color="0.79216 0.81961 0.93333 1"/> -->
    <!-- Util link for robot bottles pack -->
    <joint name="robot_bottles_util" type="fixed">
        <parent link="table" />
        <child link="robot_bottles_link" />
        <origin xyz="-0.6 0.1 0.05" />
    </joint>
    <link name="robot_bottles_link" />
    <!-- <xacro:pack parent_link_name="robot_bottles_link" pack_name="robot_pack" yaml_file_name="${robot_pack_yaml_file_name}" color="0.79216 0.81961 0.93333 1"/> -->
    <!-- Util link for both agents bottles pack -->
    <joint name="both_agents_bottles_util" type="fixed">
        <parent link="rail" />
        <child link="both_agents_bottles_link" />
        <origin xyz="-0.15 1.4 0" />
    </joint>
    <link name="both_agents_bottles_link" />
    <!-- <xacro:pack parent_link_name="both_agents_bottles_link" pack_name="both_agents_pack" yaml_file_name="${both_agents_pack_yaml_file_name}" color="0.93333333 0.89019608 0.79607843  1"/> -->
    <joint name="robot_box" type="fixed">
        <parent link="rail" />
        <child link="robot_box_link" />
        <origin rpy="0 0 1.57079632679" xyz="0.15 0.7 0" />
    </joint>
    <link name="robot_box_link">
        <inertial>
            <origin rpy="0 0 0" xyz="0.198 0.149 0.13085" />
            <mass value="3.3211" />
            <inertia ixx="0.086235" ixy="2.3962E-17" ixz="-9.9823E-17" iyy="0.12255" iyz="-3.1652E-17" izz="0.13198" />
        </inertial>
        <visual>
            <origin rpy="0 0 0" xyz="0 0 0" />
            <geometry>
                <mesh filename="package://hrc_case_study_descriptions/mesh/box.STL" scale="0.001 0.001 0.001" />
            </geometry>
            <material name="">
                <color rgba="1 0.50196 0.50196 1" />
            </material>
        </visual>
        <collision>
            <origin rpy="0 0 0" xyz="0 0 0" />
            <geometry>
                <mesh filename="package://hrc_case_study_descriptions/mesh/box.STL" scale="0.001 0.001 0.001" />
            </geometry>
        </collision>
    </link>
    <joint name="human_box" type="fixed">
        <parent link="rail" />
        <child link="human_box_link" />
        <origin rpy="0 0 1.57079632679" xyz="0.15 2.7 0" />
    </joint>
    <link name="human_box_link">
        <inertial>
            <origin rpy="0 0 0" xyz="0.198 0.149 0.13085" />
            <mass value="3.3211" />
            <inertia ixx="0.086235" ixy="2.3962E-17" ixz="-9.9823E-17" iyy="0.12255" iyz="-3.1652E-17" izz="0.13198" />
        </inertial>
        <visual>
            <origin rpy="0 0 0" xyz="0 0 0" />
            <geometry>
                <mesh filename="package://hrc_case_study_descriptions/mesh/box.STL" scale="0.001 0.001 0.001" />
            </geometry>
            <material name="">
                <color rgba="1 0.50196 0.50196 1" />
            </material>
        </visual>
        <collision>
            <origin rpy="0 0 0" xyz="0 0 0" />
            <geometry>
                <mesh filename="package://hrc_case_study_descriptions/mesh/box.STL" scale="0.001 0.001 0.001" />
            </geometry>
        </collision>
    </link>
    <!--DO NOT DELETE -->
    <gazebo>
        <plugin name="gazebo_ros_control">
            <robotNamespace>/</robotNamespace>
        </plugin>
    </gazebo>
</robot>
<!-- <xacro:macro name="robot_description" params=
 "kinematics_config:=''$(find sharework_cembre_description)/config/cembre_ur10e.yaml'
 transmission_hw_interface:=hardware_interface/PositionJointInterface "/>

 kinematics_parameters_file="$(arg kinematics_config)"
 transmission_hw_interface="$(arg transmission_hw_interface)" -->

